Workbook

Sheet README
A1: THE UNLOX ACADEMY - DA/DS TRACK
A2: Excel Minor Project - Sales Operations Analytics
A3: Interview-Grade Data Analytics Assessment · 100 Marks
A5: THE SCENARIO
A6: You have just joined the analytics team at a fast-growing multi-category retailer operating across 6 Indian cities.
A7: The head of sales has handed you 5 raw data files - Orders, Customers, Products, Sales Reps, and Targets - and asked
A8: you to answer a set of business questions before the leadership review tomorrow morning.
A10: The data is REAL-WORLD messy: duplicates, missing references, inconsistent case, invalid records, discontinued SKUs.
A11: Part of the assessment is spotting and handling these issues correctly. A wrong-looking answer isn't always wrong -
A12: sometimes the data itself is telling a story.
A14: RULES OF THE ASSESSMENT
A15: 1. Write your answer in the YELLOW cells on each question sheet. Empty answer cell = 0 marks.
... A22: MARKS DISTRIBUTION
A23: Section | B23: Topic | C23: Questions | D23: Marks
A24: Q1 | B24: Lookup Functions (VLOOKUP, INDEX-MATCH, chained lookups) | C24: 8 | D24: 25
A25: Q2 | B25: Data Cleaning & Quality Diagnostics | C25: 6 | D25: 20
A26: Q3 | B26: Conditional Aggregation (SUMIFS, COUNTIFS, IF logic) | C26: 6 | D26: 25
A27: Q4 | B27: Pivot Tables (2D pivots, % of total, calculated fields) | C27: 5 | D27: 20
A28: Q5 | B28: Advanced (Ranking, Running Totals, Multi-condition) | C28: 5 | D28: 10
B29: TOTAL | C29: 30 | D29: 100
A32: PERFORMANCE TIERS
A33: Marks | B33: Tier | C33: Interview Verdict
A34: 85 - 100 | B34: Excellent | C34: Round 1 clear - Excel not a concern
A35: 70 - 84 | B35: Good | C35: Round 1 clear with minor gaps
A36: 55 - 69 | B36: Borderline | C36: Round 1 uncertain - needs revision
A37: 40 - 54 | B37: Weak | C37: Round 1 likely reject - 2 weeks of practice needed
A38: < 40 | B38: Insufficient | C38: Round 1 reject - foundational gaps
A41: DATA SHEETS OVERVIEW
A42: Sheet | B42: Rows | C42: Key Columns | D42: Joins to
A43: Orders | B43: ~2000 | C43: order_id, order_date, customer_id, product_id, sales_rep_id, quantity, unit_price, discount_pct, final_amount, payment_status, ship_city | D43: All others
A44: Customers | B44: 300 | C44: customer_id (PK), customer_name, age, city, segment, signup_date | D44: Orders via customer_id
A45: Products | B45: 60 | C45: product_id (PK), product_name, category, unit_cost, unit_price, is_active | D45: Orders via product_id
A46: Sales_Reps | B46: 30 | C46: rep_id (PK), rep_name, region, hire_date, team_lead_id | D46: Orders via sales_rep_id, self-join via team_lead_id
A47: Targets | B47: 30 × 12 | C47: rep_id (PK), Jan-24 through Dec-24 monthly target values | D47: Sales_Reps via rep_id

Sheet Sheet1

Sheet Sheet3

Sheet Sheet4

Sheet Sheet6

Sheet Orders
A1: order_id | B1: order_date | C1: customer_id | D1: product_id | E1: sales_rep_id | F1: quantity | G1: unit_price | H1: discount_pct | I1: final_amount | J1: payment_status | K1: ship_city | L1: Category | M1: Segment | N1: Age | O1: Region | P1: unit_cost | Q1: Is_Duplicate | R1: Missing_Customer | S1: Product_Active
A2: ORD-00001 | B2: 45549 | C2: CUST-0243 | D2: PROD-014 | E2: R007 | F2: 8 | G2: 3620 | H2: 15.4 | I2: 24500.16 | J2: Completed | K2: Pune | L2: =VLOOKUP(D2, Products!A:C, 3, FALSE) -> Apparel | M2: =VLOOKUP(C2, Customers!A:E, 5, FALSE) -> SMB | N2: =VLOOKUP(C2, Customers!A:E, 3, FALSE) -> 44 | O2: =VLOOKUP(E2, Sales_Reps!A:C, 3, FALSE) -> North | P2: =VLOOKUP(D2, Products!A:E, 4, FALSE) -> 2509 | Q2: =IF(COUNTIF($A$2:A2, A2)=2, 1, 0) -> 0 | R2: =IF(ISNA(MATCH(C2, Customers!$A:$A, 0)), 1, 0) -> 0 | S2: =VLOOKUP(D2, Products!A:F, 6, FALSE) -> TRUE
A3: ORD-00002 | B3: 45340 | C3: CUST-0202 | D3: PROD-020 | E3: R005 | F3: 2 | G3: 820 | H3: 10.8 | I3: 1462.88 | J3: Pending | K3: Chennai | L3: =VLOOKUP(D3, Products!A:C, 3, FALSE) -> Apparel | M3: =VLOOKUP(C3, Customers!A:E, 5, FALSE) -> Retail | N3: =VLOOKUP(C3, Customers!A:E, 3, FALSE) -> 39 | O3: =VLOOKUP(E3, Sales_Reps!A:C, 3, FALSE) -> North | P3: =VLOOKUP(D3, Products!A:E, 4, FALSE) -> 391 | Q3: =IF(COUNTIF($A$2:A3, A3)=2, 1, 0) -> 0 | R3: =IF(ISNA(MATCH(C3, Customers!$A:$A, 0)), 1, 0) -> 0 | S3: =VLOOKUP(D3, Products!A:F, 6, FALSE) -> TRUE
A4: ORD-00003 | B4: 45371 | C4: CUST-0098 | D4: PROD-053 | E4: R014 | F4: 8 | G4: 470 | H4: 3.3 | I4: 3635.92 | J4: Pending | K4: Delhi | L4: =VLOOKUP(D4, Products!A:C, 3, FALSE) -> Sports | M4: =VLOOKUP(C4, Customers!A:E, 5, FALSE) -> Retail | N4: =VLOOKUP(C4, Customers!A:E, 3, FALSE) -> 52 | O4: =VLOOKUP(E4, Sales_Reps!A:C, 3, FALSE) -> South | P4: =VLOOKUP(D4, Products!A:E, 4, FALSE) -> 302 | Q4: =IF(COUNTIF($A$2:A4, A4)=2, 1, 0) -> 0 | R4: =IF(ISNA(MATCH(C4, Customers!$A:$A, 0)), 1, 0) -> 0 | S4: =VLOOKUP(D4, Products!A:F, 6, FALSE) -> FALSE
A5: ORD-00004 | B5: 45413 | C5: CUST-0071 | D5: PROD-028 | E5: R006 | F5: 1 | G5: 3660 | H5: 15.7 | I5: 3085.38 | J5: Completed | K5: Delhi | L5: =VLOOKUP(D5, Products!A:C, 3, FALSE) -> Grocery | M5: =VLOOKUP(C5, Customers!A:E, 5, FALSE) -> Corporate | N5: =VLOOKUP(C5, Customers!A:E, 3, FALSE) -> 46 | O5: =VLOOKUP(E5, Sales_Reps!A:C, 3, FALSE) -> North | P5: =VLOOKUP(D5, Products!A:E, 4, FALSE) -> 2214 | Q5: =IF(COUNTIF($A$2:A5, A5)=2, 1, 0) -> 0 | R5: =IF(ISNA(MATCH(C5, Customers!$A:$A, 0)), 1, 0) -> 0 | S5: =VLOOKUP(D5, Products!A:F, 6, FALSE) -> FALSE
A6: ORD-00005 | B6: 45611 | C6: CUST-0180 | D6: PROD-012 | E6: R008 | F6: 1 | G6: 3160 | H6: 26 | I6: 2338.4 | J6: Completed | K6: Chennai | L6: =VLOOKUP(D6, Products!A:C, 3, FALSE) -> Apparel | M6: =VLOOKUP(C6, Customers!A:E, 5, FALSE) -> Retail | N6: =VLOOKUP(C6, Customers!A:E, 3, FALSE) -> 36 | O6: =VLOOKUP(E6, Sales_Reps!A:C, 3, FALSE) -> North | P6: =VLOOKUP(D6, Products!A:E, 4, FALSE) -> 1886 | Q6: =IF(COUNTIF($A$2:A6, A6)=2, 1, 0) -> 0 | R6: =IF(ISNA(MATCH(C6, Customers!$A:$A, 0)), 1, 0) -> 0 | S6: =VLOOKUP(D6, Products!A:F, 6, FALSE) -> TRUE
A7: ORD-00006 | B7: 45406 | C7: CUST-0275 | D7: PROD-032 | E7: R025 | F7: 4 | G7: 370 | H7: 29 | I7: 1050.8 | J7: Completed | K7: Mumbai | L7: =VLOOKUP(D7, Products!A:C, 3, FALSE) -> Home | M7: =VLOOKUP(C7, Customers!A:E, 5, FALSE) -> Retail | N7: =VLOOKUP(C7, Customers!A:E, 3, FALSE) -> 36 | O7: =VLOOKUP(E7, Sales_Reps!A:C, 3, FALSE) -> West | P7: =VLOOKUP(D7, Products!A:E, 4, FALSE) -> 288 | Q7: =IF(COUNTIF($A$2:A7, A7)=2, 1, 0) -> 0 | R7: =IF(ISNA(MATCH(C7, Customers!$A:$A, 0)), 1, 0) -> 0 | S7: =VLOOKUP(D7, Products!A:F, 6, FALSE) -> TRUE
A8: ORD-00007 | B8: 45455 | C8: CUST-0293 | D8: PROD-057 | E8: R024 | F8: 3 | G8: 960 | H8: 5.8 | I8: 2712.96 | J8: Completed | K8: Bengaluru | L8: =VLOOKUP(D8, Products!A:C, 3, FALSE) -> Sports | M8: =VLOOKUP(C8, Customers!A:E, 5, FALSE) -> Retail | N8: =VLOOKUP(C8, Customers!A:E, 3, FALSE) -> 27 | O8: =VLOOKUP(E8, Sales_Reps!A:C, 3, FALSE) -> West | P8: =VLOOKUP(D8, Products!A:E, 4, FALSE) -> 705 | Q8: =IF(COUNTIF($A$2:A8, A8)=2, 1, 0) -> 0 | R8: =IF(ISNA(MATCH(C8, Customers!$A:$A, 0)), 1, 0) -> 0 | S8: =VLOOKUP(D8, Products!A:F, 6, FALSE) -> TRUE
A9: ORD-00008 | B9: 45617 | C9: CUST-0281 | D9: PROD-007 | E9: R019 | F9: 8 | G9: 1430 | H9: 2.4 | I9: 11165.44 | J9: Completed | K9: Bengaluru | L9: =VLOOKUP(D9, Products!A:C, 3, FALSE) -> Electronics | M9: =VLOOKUP(C9, Customers!A:E, 5, FALSE) -> Corporate | N9: =VLOOKUP(C9, Customers!A:E, 3, FALSE) -> 57 | O9: =VLOOKUP(E9, Sales_Reps!A:C, 3, FALSE) -> East | P9: =VLOOKUP(D9, Products!A:E, 4, FALSE) -> 861 | Q9: =IF(COUNTIF($A$2:A9, A9)=2, 1, 0) -> 0 | R9: =IF(ISNA(MATCH(C9, Customers!$A:$A, 0)), 1, 0) -> 0 | S9: =VLOOKUP(D9, Products!A:F, 6, FALSE) -> TRUE
A10: ORD-00009 | B10: 45549 | C10: CUST-0260 | D10: PROD-038 | E10: R008 | F10: 3 | G10: 5490 | H10: 14.2 | I10: 14131.26 | J10: Completed | K10: Bengaluru | L10: =VLOOKUP(D10, Products!A:C, 3, FALSE) -> Home | M10: =VLOOKUP(C10, Customers!A:E, 5, FALSE) -> Retail | N10: =VLOOKUP(C10, Customers!A:E, 3, FALSE) -> 42 | O10: =VLOOKUP(E10, Sales_Reps!A:C, 3, FALSE) -> North | P10: =VLOOKUP(D10, Products!A:E, 4, FALSE) -> 2549 | Q10: =IF(COUNTIF($A$2:A10, A10)=2, 1, 0) -> 0 | R10: =IF(ISNA(MATCH(C10, Customers!$A:$A, 0)), 1, 0) -> 0 | S10: =VLOOKUP(D10, Products!A:F, 6, FALSE) -> TRUE
A11: ORD-00010 | B11: 45396 | C11: CUST-0147 | D11: PROD-030 | E11: R028 | F11: 3 | G11: 970 | H11: 1.2 | I11: 2875.08 | J11: Completed | K11: Pune | L11: =VLOOKUP(D11, Products!A:C, 3, FALSE) -> Grocery | M11: =VLOOKUP(C11, Customers!A:E, 5, FALSE) -> Retail | N11: =VLOOKUP(C11, Customers!A:E, 3, FALSE) -> 56 | O11: =VLOOKUP(E11, Sales_Reps!A:C, 3, FALSE) -> West | P11: =VLOOKUP(D11, Products!A:E, 4, FALSE) -> 434 | Q11: =IF(COUNTIF($A$2:A11, A11)=2, 1, 0) -> 0 | R11: =IF(ISNA(MATCH(C11, Customers!$A:$A, 0)), 1, 0) -> 0 | S11: =VLOOKUP(D11, Products!A:F, 6, FALSE) -> TRUE
A12: ORD-00011 | B12: 45560 | C12: CUST-0204 | D12: PROD-024 | E12: R010 | F12: 7 | G12: 2270 | H12: 7.1 | I12: 14761.81 | J12: Pending | K12: Hyderabad | L12: =VLOOKUP(D12, Products!A:C, 3, FALSE) -> Grocery | M12: =VLOOKUP(C12, Customers!A:E, 5, FALSE) -> Retail | N12: =VLOOKUP(C12, Customers!A:E, 3, FALSE) -> 60 | O12: =VLOOKUP(E12, Sales_Reps!A:C, 3, FALSE) -> South | P12: =VLOOKUP(D12, Products!A:E, 4, FALSE) -> 1203 | Q12: =IF(COUNTIF($A$2:A12, A12)=2, 1, 0) -> 0 | R12: =IF(ISNA(MATCH(C12, Customers!$A:$A, 0)), 1, 0) -> 0 | S12: =VLOOKUP(D12, Products!A:F, 6, FALSE) -> TRUE
A13: ORD-00012 | B13: 45332 | C13: CUST-0147 | D13: PROD-010 | E13: R024 | F13: 9 | G13: 2640 | H13: 21.7 | I13: 18604.08 | J13: Completed | K13: Pune | L13: =VLOOKUP(D13, Products!A:C, 3, FALSE) -> Electronics | M13: =VLOOKUP(C13, Customers!A:E, 5, FALSE) -> Retail | N13: =VLOOKUP(C13, Customers!A:E, 3, FALSE) -> 56 | O13: =VLOOKUP(E13, Sales_Reps!A:C, 3, FALSE) -> West | P13: =VLOOKUP(D13, Products!A:E, 4, FALSE) -> 1149 | Q13: =IF(COUNTIF($A$2:A13, A13)=2, 1, 0) -> 0 | R13: =IF(ISNA(MATCH(C13, Customers!$A:$A, 0)), 1, 0) -> 0 | S13: =VLOOKUP(D13, Products!A:F, 6, FALSE) -> TRUE
... A2001: ORD-02000 | B2001: 45325 | C2001: CUST-0238 | D2001: PROD-034 | E2001: R023 | F2001: 6 | G2001: 5080 | H2001: 28.1 | I2001: 21915.12 | J2001: Completed | K2001: Delhi | L2001: =VLOOKUP(D2001, Products!A:C, 3, FALSE) -> Home | M2001: =VLOOKUP(C2001, Customers!A:E, 5, FALSE) -> Retail | N2001: =VLOOKUP(C2001, Customers!A:E, 3, FALSE) -> 49 | O2001: =VLOOKUP(E2001, Sales_Reps!A:C, 3, FALSE) -> East | P2001: =VLOOKUP(D2001, Products!A:E, 4, FALSE) -> 2459 | Q2001: =IF(COUNTIF($A$2:A2001, A2001)=2, 1, 0) -> 0 | R2001: =IF(ISNA(MATCH(C2001, Customers!$A:$A, 0)), 1, 0) -> 0 | S2001: =VLOOKUP(D2001, Products!A:F, 6, FALSE) -> TRUE
A2004: 5.2 | B2004: =SUMIFS(I1:I2001, B1:B2001, "<="&DATE(2024,8,31)) -> 18050690
A2005: 5.5 | B2005: =_xlfn.MAXIFS(I1:I2001, K1:K2001, "Bengaluru",L1:L2001, "Grocery") -> 22134

Sheet Customers
A1: customer_id | B1: customer_name | C1: age | D1: city | E1: segment | F1: signup_date | G1: Std_City
A2: CUST-0001 | B2: Amit Agarwal | C2: 36 | D2: Pune | E2: Retail | F2: 44819 | G2: =PROPER(D2) -> Pune
A3: CUST-0002 | B3: Vihaan Malhotra | C3: 42 | D3: Pune | E3: Corporate | F3: 44984 | G3: =PROPER(D3) -> Pune
A4: CUST-0003 | B4: Navya Malhotra | C4: 33 | D4: Mumbai | E4: Retail | F4: 44059 | G4: =PROPER(D4) -> Mumbai
A5: CUST-0004 | B5: Aaradhya Mehta | C5: 53 | D5: delhi | E5: Retail | F5: 44054 | G5: =PROPER(D5) -> Delhi
A6: CUST-0005 | B6: Myra Malhotra | C6: 52 | D6: Chennai | E6: Corporate | F6: 45037 | G6: =PROPER(D6) -> Chennai
A7: CUST-0006 | B7: Shaurya Iyer | C7: 44 | D7: Pune | E7: SMB | F7: 44302 | G7: =PROPER(D7) -> Pune
A8: CUST-0007 | B8: Dhruv Joshi | C8: 47 | D8: Bengaluru | E8: Retail | F8: 44498 | G8: =PROPER(D8) -> Bengaluru
A9: CUST-0008 | B9: Kavita Malhotra | C9: 39 | D9: Pune | E9: SMB | F9: 45162 | G9: =PROPER(D9) -> Pune
A10: CUST-0009 | B10: Neha Malhotra | C10: 61 | D10: Mumbai | E10: Retail | F10: 44343 | G10: =PROPER(D10) -> Mumbai
A11: CUST-0010 | B11: Aaradhya Gupta | C11: 61 | D11: Mumbai | E11: SMB | F11: 44975 | G11: =PROPER(D11) -> Mumbai
A12: CUST-0011 | B12: Diya Menon | C12: 41 | D12: Chennai | E12: Corporate | F12: 44821 | G12: =PROPER(D12) -> Chennai
A13: CUST-0012 | B13: Prisha Desai | C13: 43 | D13: Pune | E13: Retail | F13: 44718 | G13: =PROPER(D13) -> Pune
... A301: CUST-0300 | B301: Rohit Nair | C301: 38 | D301: Mumbai | E301: Retail | F301: 43932 | G301: =PROPER(D301) -> Mumbai

Sheet Products
A1: product_id | B1: product_name | C1: category | D1: unit_cost | E1: unit_price | F1: is_active
A2: PROD-001 | B2: Smartphone Pro | C2: Electronics | D2: 2405 | E2: 5330 | F2: TRUE
A3: PROD-002 | B3: Wireless Earbuds | C3: Electronics | D3: 1052 | E3: 2600 | F3: TRUE
A4: PROD-003 | B4: Smart Watch | C4: Electronics | D4: 1665 | E4: 3570 | F4: TRUE
A5: PROD-004 | B5: Laptop Bag | C5: Electronics | D5: 1559 | E5: 3870 | F5: TRUE
A6: PROD-005 | B6: Power Bank | C6: Electronics | D6: 128 | E6: 300 | F6: TRUE
A7: PROD-006 | B7: Bluetooth Speaker | C7: Electronics | D7: 2865 | E7: 3970 | F7: TRUE
A8: PROD-007 | B8: USB-C Cable | C8: Electronics | D8: 861 | E8: 1430 | F8: TRUE
A9: PROD-008 | B9: Wireless Mouse | C9: Electronics | D9: 1259 | E9: 2660 | F9: FALSE
A10: PROD-009 | B10: Mechanical Keyboard | C10: Electronics | D10: 517 | E10: 1220 | F10: TRUE
A11: PROD-010 | B11: Tablet Stand | C11: Electronics | D11: 1149 | E11: 2640 | F11: TRUE
A12: PROD-011 | B12: Cotton T-Shirt | C12: Apparel | D12: 1748 | E12: 3450 | F12: TRUE
A13: PROD-012 | B13: Denim Jeans | C13: Apparel | D13: 1886 | E13: 3160 | F13: TRUE
... A61: PROD-060 | B61: Gym Gloves | C61: Sports | D61: 147 | E61: 190 | F61: TRUE

Sheet Sales_Reps
A1: rep_id | B1: rep_name | C1: region | D1: hire_date | E1: team_lead_id
A2: R001 | B2: Rajesh Malhotra | C2: North | D2: 44207
A3: R002 | B3: Sunita Malhotra | C3: North | D3: 44028
A4: R003 | B4: Amit Singh | C4: North | D4: 43651
A5: R004 | B5: Priya Singh | C5: North | D5: 44907
A6: R005 | B6: Vikram Patel | C6: North | D6: 43588 | E6: R001
A7: R006 | B7: Neha Desai | C7: North | D7: 44131 | E7: R001
A8: R007 | B8: Suresh Menon | C8: North | D8: 43493 | E8: R001
A9: R008 | B9: Kavita Patel | C9: North | D9: 44693 | E9: R001
A10: R009 | B10: Manoj Patel | C10: South | D10: 44804 | E10: R002
A11: R010 | B11: Divya Rao | C11: South | D11: 43904 | E11: R002
A12: R011 | B12: Anil Verma | C12: South | D12: 44622 | E12: R002
A13: R012 | B13: Pooja Nair | C13: South | D13: 44890 | E13: R002
A14: R013 | B14: Sanjay Kapoor | C14: South | D14: 45215 | E14: R002
A15: R014 | B15: Ritu Menon | C15: South | D15: 44469 | E15: R002
A16: R015 | B16: Deepak Shah | C16: South | D16: 45231 | E16: R002
A17: R016 | B17: Anjali Chopra | C17: South | D17: 43614 | E17: R002
... A31: R030 | B31: Kiran Bhatt | C31: West | D31: 44506 | E31: R004

Sheet Targets
A1: rep_id | B1: Jan-24 | C1: Feb-24 | D1: Mar-24 | E1: Apr-24 | F1: May-24 | G1: Jun-24 | H1: Jul-24 | I1: Aug-24 | J1: Sep-24 | K1: Oct-24 | L1: Nov-24 | M1: Dec-24
A2: R001 | B2: 231324 | C2: 171682 | D2: 234376 | E2: 326967 | F2: 350588 | G2: 385324 | H2: 307980 | I2: 327947 | J2: 181016 | K2: 374039 | L2: 212805 | M2: 405999
A3: R002 | B3: 438126 | C3: 346266 | D3: 329993 | E3: 370744 | F3: 294660 | G3: 341556 | H3: 151934 | I3: 223794 | J3: 438641 | K3: 344308 | L3: 296172 | M3: 304288
A4: R003 | B4: 358703 | C4: 320519 | D4: 327321 | E4: 298753 | F4: 254636 | G4: 351929 | H4: 264723 | I4: 216459 | J4: 391945 | K4: 362426 | L4: 289199 | M4: 301863
A5: R004 | B5: 389594 | C5: 376422 | D5: 324156 | E5: 420255 | F5: 409107 | G5: 269954 | H5: 179097 | I5: 370568 | J5: 387395 | K5: 243454 | L5: 232530 | M5: 201999
A6: R005 | B6: 436862 | C6: 391158 | D6: 340224 | E6: 170548 | F6: 229390 | G6: 349525 | H6: 154683 | I6: 320848 | J6: 354452 | K6: 377180 | L6: 342347 | M6: 183362
A7: R006 | B7: 348734 | C7: 358191 | D7: 250385 | E7: 219657 | F7: 249365 | G7: 435704 | H7: 260892 | I7: 250741 | J7: 358402 | K7: 379858 | L7: 213280 | M7: 224634
A8: R007 | B8: 280057 | C8: 330342 | D8: 336856 | E8: 227425 | F8: 233647 | G8: 307088 | H8: 370724 | I8: 440008 | J8: 406347 | K8: 217357 | L8: 299289 | M8: 214568
A9: R008 | B9: 252886 | C9: 206057 | D9: 318209 | E9: 411230 | F9: 448660 | G9: 171135 | H9: 305339 | I9: 432264 | J9: 294273 | K9: 371409 | L9: 284207 | M9: 437068
A10: R009 | B10: 268752 | C10: 393256 | D10: 310649 | E10: 246237 | F10: 271287 | G10: 314545 | H10: 406506 | I10: 334930 | J10: 348625 | K10: 408928 | L10: 243749 | M10: 418409
A11: R010 | B11: 384734 | C11: 156698 | D11: 283679 | E11: 276085 | F11: 409270 | G11: 285230 | H11: 304233 | I11: 178221 | J11: 284216 | K11: 287373 | L11: 229082 | M11: 298969
A12: R011 | B12: 186029 | C12: 151419 | D12: 253251 | E12: 379757 | F12: 204209 | G12: 179396 | H12: 378008 | I12: 182649 | J12: 267772 | K12: 350352 | L12: 358042 | M12: 359960
A13: R012 | B13: 352158 | C13: 251181 | D13: 321255 | E13: 300863 | F13: 241731 | G13: 393275 | H13: 313561 | I13: 283604 | J13: 429065 | K13: 194420 | L13: 254168 | M13: 389283
... A31: R030 | B31: 151584 | C31: 221679 | D31: 385157 | E31: 290386 | F31: 236041 | G31: 407985 | H31: 184446 | I31: 342894 | J31: 180344 | K31: 292917 | L31: 314858 | M31: 364057

Sheet Q1_Lookups
A1: Q1 - LOOKUP FUNCTIONS (25 marks total)
A2: VLOOKUP · INDEX-MATCH · Two-way lookup · Chain lookup · Approximate lookup · Self-join
A4: Q# | B4: Question | C4: Marks | D4: Hint | E4: Your Answer | F4: Format
A5: Q1.1 | B5: For order ORD-00234, what is the customer_id? | C5: 3 | D5: Simple VLOOKUP on Orders sheet. | E5: =VLOOKUP("ORD-00234", Orders!A:C, 3, FALSE) -> CUST-0173 | F5: CUST-####
A6: Q1.2 | B6: For order ORD-00456, what is the product_name? (You will need to look up the product_id first, then find its name in Products.) | C6: 3 | D6: Two-step lookup, or nested VLOOKUP. | E6: =VLOOKUP(VLOOKUP("ORD-00456", Orders!A:D, 4, FALSE), Products!A:B, 2, FALSE) -> Dumbbells 5kg | F6: Text
A7: Q1.3 | B7: For order ORD-00987, what is the rep_name of the sales rep? Note: the rep_name is in a column that appears to the LEFT of what you might look up first. | C7: 3 | D7: VLOOKUP has directional limits - INDEX/MATCH does not. | E7: =INDEX(Sales_Reps!B:B, MATCH(VLOOKUP("ORD-00987", Orders!A:E, 5, FALSE), Sales_Reps!A:A, 0)) -> Nisha Menon | F7: Text
A8: Q1.4 | B8: From the Targets sheet, what is the target value for rep R012 in the month Mar-24? | C8: 4 | D8: Two-way lookup: row = rep_id, column = month. | E8: =INDEX(Targets!A1:M31, MATCH("R012", Targets!A:A, 0), MATCH("Mar-24", Targets!1:1, 0)) -> 321255 | F8: Whole number
A9: Q1.5 | B9: For order ORD-01500, what is the CATEGORY of the product ordered? (Chain: order → product_id → category) | C9: 4 | D9: Multi-hop lookup across sheets. | E9: =VLOOKUP(VLOOKUP("ORD-01500", Orders!A:D, 4, FALSE), Products!A:C, 3, FALSE) -> Electronics | F9: Text
A10: Q1.6 | B10: For order ORD-00789, which DISCOUNT SLAB does it fall in? Use the slab table below (rows 20-24). Slab breakpoints are the LOWER bound of each range. | C10: 3 | D10: Approximate-match VLOOKUP (sort ascending, TRUE / omit last arg). | E10: =VLOOKUP(VLOOKUP("ORD-00789*", Orders!A:H, 8, FALSE)*1, $B$18:$C$21, 2, TRUE) -> Bronze | F10: Text
A11: Q1.7 | B11: For order ORD-01234, in one cell produce the string: "<rep_name> (<sales_region>)" - e.g. "Amit Singh (South)". | C11: 3 | D11: Two lookups joined with & or CONCATENATE. | E11: =VLOOKUP(VLOOKUP("ORD-01234", Orders!A:E, 5, FALSE), Sales_Reps!A:B, 2, FALSE) & " (" & VLOOKUP(VLOOKUP("ORD-01234", Orders!A:E, 5, FALSE), Sales_Reps!A:C, 3, FALSE) & ")" -> Sanjay Kapoor (South) | F11: Text
A12: Q1.8 | B12: What is the rep_name of the TEAM LEAD for rep R017? (The Sales_Reps sheet has team_lead_id - you need to self-join to find that person's name.) | C12: 2 | D12: Look up the team_lead_id, then look up THAT id's rep_name. | E12: =VLOOKUP(VLOOKUP("R017", Sales_Reps!A:E, 5, FALSE), Sales_Reps!A:B, 2, FALSE) -> Amit Singh | F12: Text
B15: DISCOUNT SLAB REFERENCE TABLE (use for Q1.6)
B17: Discount % (Lower) | C17: Slab
B18: 0 | C18: Bronze
B19: 5 | C19: Silver
B20: 15 | C20: Gold
B21: 25 | C21: Platinum

Sheet Q2_Cleaning
A1: Q2 - DATA CLEANING & QUALITY DIAGNOSTICS (20 marks total)
A2: Duplicates · Whitespace · Case Inconsistency · Referential Integrity · Discontinued SKUs · Anomaly Patterns
A4: Q# | B4: Question | C4: Marks | D4: Hint | E4: Your Answer | F4: Format
A5: Q2.1 | B5: How many DUPLICATE rows exist in the Orders sheet (i.e., how many order_id values appear more than once)? Count each duplicate as ONE (not the extras). | C5: 3 | D5: COUNTIF > 1, then count. Watch what you're counting - rows or IDs. | E5: {=SUMPRODUCT((COUNTIF(Orders!A2:A2001, Orders!A2:A2001)>1)/COUNTIF(Orders!A2:A2001, Orders!A2:A2001))} -> 20 | F5: Whole number
A6: Q2.2 | B6: How many customers in the Customers sheet have LEADING or TRAILING whitespace in their customer_name? | C6: 3 | D6: Compare LEN vs LEN(TRIM). Or use SUMPRODUCT with a boolean. | E6: {=SUMPRODUCT(--(LEN(Customers!B2:B301)<>LEN(TRIM(Customers!B2:B301))))} -> 15 | F6: Whole number
A7: Q2.3 | B7: The Customers sheet has some cities in inconsistent case (e.g., "mumbai", "MUMBAI", "Mumbai"). How many DISTINCT cities exist AFTER standardizing case? | C7: 3 | D7: Combine PROPER/UPPER with a de-dup count. SUMPRODUCT + 1/COUNTIF trick works. | E7: {=SUMPRODUCT(1/COUNTIF(Customers!D2:D301, Customers!D2:D301))} -> 6 | F7: Whole number
A8: Q2.4 | B8: How many orders reference a customer_id that DOES NOT EXIST in the Customers sheet? (Broken foreign key) | C8: 4 | D8: Use MATCH with ISNA/ISERROR, then count. | E8: =SUM(Orders!R2:R2001) -> 30 | F8: Whole number
A9: Q2.5 | B9: How many orders reference a product that is currently DISCONTINUED (is_active = FALSE in the Products sheet)? | C9: 3 | D9: VLOOKUP the is_active flag, then count where FALSE. | E9: =COUNTIF(Orders!$S$2:$S$2001, FALSE) -> 174 | F9: Whole number
A10: Q2.6 | B10: Find the "suspicious pattern": how many orders have payment_status = "Cancelled" AND a discount_pct > 20%? (This pattern often indicates promo abuse - a real-world diagnostic query.) | C10: 4 | D10: COUNTIFS with two criteria. | E10: =COUNTIFS(Orders!J2:J2001, "Cancelled", Orders!H2:H2001, ">20") -> 58 | F10: Whole number

Sheet Q3_Aggregation
A1: Q3 - CONDITIONAL AGGREGATION (25 marks total)
A2: SUMIFS · COUNTIFS · AVERAGEIFS · Nested IF logic · Multi-sheet aggregation · Top-N logic | J2: Rep ID | K2: Total Revenue | L2: Rep Name | M2: Rank | N2: Actual Revenue | O2: Target Revenue | P2: Ratio
J3: R001 | K3: =SUMIFS(Orders!I:I, Orders!E:E, J3) -> 789849.6 | L3: =VLOOKUP(Q3_Aggregation!J3, Sales_Reps!A:B, 2, FALSE) -> Rajesh Malhotra | M3: =_xlfn.RANK.EQ(Q3_Aggregation!K3, Q3_Aggregation!$K$3:$K$32, 0) -> 23 | N3: =SUMIFS(Orders!I:I, Orders!E:E, "R015", Orders!B:B, ">="&DATE(2024,11,1), Orders!B:B, "<="&DATE(2024,11,30)) -> 97394.65 | O3: =INDEX(Targets!A:M, MATCH("R015", Targets!A:A, 0), MATCH("Nov-24", Targets!A1:M1, 0)) -> 418857 | P3: =N3/O3 -> 0.23252482
A4: Q# | B4: Question | C4: Marks | D4: Hint | E4: Your Answer | F4: Format | J4: R002 | K4: =SUMIFS(Orders!I:I, Orders!E:E, J4) -> 980063.66 | L4: =VLOOKUP(Q3_Aggregation!J4, Sales_Reps!A:B, 2, FALSE) -> Sunita Malhotra | M4: =_xlfn.RANK.EQ(Q3_Aggregation!K4, Q3_Aggregation!$K$3:$K$32, 0) -> 9
A5: Q3.1 | B5: What is the TOTAL REVENUE (sum of final_amount) for orders in Q3 2024 (Jul-Sep) where ship_city is Mumbai? | C5: 4 | D5: SUMIFS with 3 conditions: date >= start, date <= end, city = Mumbai. Beware case issues. | E5: =SUMIFS(Orders!I2:I2001, Orders!K2:K2001, "Mumbai", Orders!B2:B2001, ">="&DATE(2024,7,1), Orders!B2:B2001, "<="&DATE(2024,9,30)) -> 1217239 | F5: Currency | J5: R003 | K5: =SUMIFS(Orders!I:I, Orders!E:E, J5) -> 986692.91 | L5: =VLOOKUP(Q3_Aggregation!J5, Sales_Reps!A:B, 2, FALSE) -> Amit Singh | M5: =_xlfn.RANK.EQ(Q3_Aggregation!K5, Q3_Aggregation!$K$3:$K$32, 0) -> 7
A6: Q3.2 | B6: How many orders have discount_pct > 15% AND payment_status = "Completed"? | C6: 3 | D6: COUNTIFS with two conditions. | E6: =COUNTIFS(Orders!H2:H2001, ">15", Orders!J2:J2001, "Completed") -> 723 | F6: Whole number | J6: R004 | K6: =SUMIFS(Orders!I:I, Orders!E:E, J6) -> 589026.29 | L6: =VLOOKUP(Q3_Aggregation!J6, Sales_Reps!A:B, 2, FALSE) -> Priya Singh | M6: =_xlfn.RANK.EQ(Q3_Aggregation!K6, Q3_Aggregation!$K$3:$K$32, 0) -> 29
A7: Q3.3 | B7: What is the AVERAGE final_amount for orders where the product CATEGORY is "Electronics" AND the customer SEGMENT is "Corporate"? Note: Both fields come from OTHER sheets - you'll need helper columns. | C7: 5 | D7: Helper columns in Orders: VLOOKUP category from Products, VLOOKUP segment from Customers. Then AVERAGEIFS. | E7: =AVERAGEIFS(Orders!I:I, Orders!L:L, "Electronics", Orders!M:M, "Corporate") -> 13981.402 | F7: Currency | J7: R005 | K7: =SUMIFS(Orders!I:I, Orders!E:E, J7) -> 782445.33 | L7: =VLOOKUP(Q3_Aggregation!J7, Sales_Reps!A:B, 2, FALSE) -> Vikram Patel | M7: =_xlfn.RANK.EQ(Q3_Aggregation!K7, Q3_Aggregation!$K$3:$K$32, 0) -> 24
A8: Q3.4 | B8: What is the COMBINED REVENUE of the TOP 3 reps by total revenue? (Sum of the 3 highest rep totals.) | C8: 4 | D8: Compute per-rep totals, then use SUMPRODUCT with LARGE, or sort and sum top 3. | E8: {=SUMPRODUCT(LARGE(K3:K32, {1,2,3}))} -> 3342678.5 | F8: Currency | J8: R006 | K8: =SUMIFS(Orders!I:I, Orders!E:E, J8) -> 1138648.7 | L8: =VLOOKUP(Q3_Aggregation!J8, Sales_Reps!A:B, 2, FALSE) -> Neha Desai | M8: =_xlfn.RANK.EQ(Q3_Aggregation!K8, Q3_Aggregation!$K$3:$K$32, 0) -> 1
A9: Q3.5 | B9: For rep R015 in Nov-24: compute the actual revenue and compare to the target (from Targets sheet). Report the PERFORMANCE TIER using: <80% → "Below", 80-120% → "On Track", >120% → "Exceeds". Return only the tier text. | C9: 5 | D9: Nested IF (or IFS): compute actual/target ratio, then classify. | E9: =IF(P3 < 0.8, "Below", IF(P3 <= 1.2, "On Track", "Exceeds")) -> Below | F9: Text | J9: R007 | K9: =SUMIFS(Orders!I:I, Orders!E:E, J9) -> 855749.68 | L9: =VLOOKUP(Q3_Aggregation!J9, Sales_Reps!A:B, 2, FALSE) -> Suresh Menon | M9: =_xlfn.RANK.EQ(Q3_Aggregation!K9, Q3_Aggregation!$K$3:$K$32, 0) -> 19
A10: Q3.6 | B10: What is the TOTAL revenue from Corporate segment customers aged between 30 and 40 (both inclusive)? | C10: 4 | D10: Helper columns for age and segment. Then SUMIFS with numeric range. | E10: =SUMIFS(Orders!I:I, Orders!M:M, "Corporate", Orders!N:N, ">=30", Orders!N:N, "<=40") -> 982568.4 | F10: Currency | J10: R008 | K10: =SUMIFS(Orders!I:I, Orders!E:E, J10) -> 861553.33 | L10: =VLOOKUP(Q3_Aggregation!J10, Sales_Reps!A:B, 2, FALSE) -> Kavita Patel | M10: =_xlfn.RANK.EQ(Q3_Aggregation!K10, Q3_Aggregation!$K$3:$K$32, 0) -> 18
J11: R009 | K11: =SUMIFS(Orders!I:I, Orders!E:E, J11) -> 914554.72 | L11: =VLOOKUP(Q3_Aggregation!J11, Sales_Reps!A:B, 2, FALSE) -> Manoj Patel | M11: =_xlfn.RANK.EQ(Q3_Aggregation!K11, Q3_Aggregation!$K$3:$K$32, 0) -> 12
J12: R010 | K12: =SUMIFS(Orders!I:I, Orders!E:E, J12) -> 880345.2 | L12: =VLOOKUP(Q3_Aggregation!J12, Sales_Reps!A:B, 2, FALSE) -> Divya Rao | M12: =_xlfn.RANK.EQ(Q3_Aggregation!K12, Q3_Aggregation!$K$3:$K$32, 0) -> 17
J13: R011 | K13: =SUMIFS(Orders!I:I, Orders!E:E, J13) -> 735207.76 | L13: =VLOOKUP(Q3_Aggregation!J13, Sales_Reps!A:B, 2, FALSE) -> Anil Verma | M13: =_xlfn.RANK.EQ(Q3_Aggregation!K13, Q3_Aggregation!$K$3:$K$32, 0) -> 28
J14: R012 | K14: =SUMIFS(Orders!I:I, Orders!E:E, J14) -> 901394.32 | L14: =VLOOKUP(Q3_Aggregation!J14, Sales_Reps!A:B, 2, FALSE) -> Pooja Nair | M14: =_xlfn.RANK.EQ(Q3_Aggregation!K14, Q3_Aggregation!$K$3:$K$32, 0) -> 14
J15: R013 | K15: =SUMIFS(Orders!I:I, Orders!E:E, J15) -> 811524.38 | L15: =VLOOKUP(Q3_Aggregation!J15, Sales_Reps!A:B, 2, FALSE) -> Sanjay Kapoor | M15: =_xlfn.RANK.EQ(Q3_Aggregation!K15, Q3_Aggregation!$K$3:$K$32, 0) -> 22
J16: R014 | K16: =SUMIFS(Orders!I:I, Orders!E:E, J16) -> 995713.54 | L16: =VLOOKUP(Q3_Aggregation!J16, Sales_Reps!A:B, 2, FALSE) -> Ritu Menon | M16: =_xlfn.RANK.EQ(Q3_Aggregation!K16, Q3_Aggregation!$K$3:$K$32, 0) -> 6
J17: R015 | K17: =SUMIFS(Orders!I:I, Orders!E:E, J17) -> 1091740.2 | L17: =VLOOKUP(Q3_Aggregation!J17, Sales_Reps!A:B, 2, FALSE) -> Deepak Shah | M17: =_xlfn.RANK.EQ(Q3_Aggregation!K17, Q3_Aggregation!$K$3:$K$32, 0) -> 3
J18: R016 | K18: =SUMIFS(Orders!I:I, Orders!E:E, J18) -> 814563.71 | L18: =VLOOKUP(Q3_Aggregation!J18, Sales_Reps!A:B, 2, FALSE) -> Anjali Chopra | M18: =_xlfn.RANK.EQ(Q3_Aggregation!K18, Q3_Aggregation!$K$3:$K$32, 0) -> 21
J19: R017 | K19: =SUMIFS(Orders!I:I, Orders!E:E, J19) -> 780384.41 | L19: =VLOOKUP(Q3_Aggregation!J19, Sales_Reps!A:B, 2, FALSE) -> Naveen Singh | M19: =_xlfn.RANK.EQ(Q3_Aggregation!K19, Q3_Aggregation!$K$3:$K$32, 0) -> 25
J20: R018 | K20: =SUMIFS(Orders!I:I, Orders!E:E, J20) -> 1112289.6 | L20: =VLOOKUP(Q3_Aggregation!J20, Sales_Reps!A:B, 2, FALSE) -> Shalini Patel | M20: =_xlfn.RANK.EQ(Q3_Aggregation!K20, Q3_Aggregation!$K$3:$K$32, 0) -> 2
J21: R019 | K21: =SUMIFS(Orders!I:I, Orders!E:E, J21) -> 971183.52 | L21: =VLOOKUP(Q3_Aggregation!J21, Sales_Reps!A:B, 2, FALSE) -> Prakash Shah | M21: =_xlfn.RANK.EQ(Q3_Aggregation!K21, Q3_Aggregation!$K$3:$K$32, 0) -> 10
J22: R020 | K22: =SUMIFS(Orders!I:I, Orders!E:E, J22) -> 906107.71 | L22: =VLOOKUP(Q3_Aggregation!J22, Sales_Reps!A:B, 2, FALSE) -> Meera Iyer | M22: =_xlfn.RANK.EQ(Q3_Aggregation!K22, Q3_Aggregation!$K$3:$K$32, 0) -> 13
... J32: R030 | K32: =SUMIFS(Orders!I:I, Orders!E:E, J32) -> 747624.37 | L32: =VLOOKUP(Q3_Aggregation!J32, Sales_Reps!A:B, 2, FALSE) -> Kiran Bhatt | M32: =_xlfn.RANK.EQ(Q3_Aggregation!K32, Q3_Aggregation!$K$3:$K$32, 0) -> 27

Sheet Q4_Pivot
A1: Q4 - PIVOT TABLES (20 marks total)
A2: 2D Pivots · Filters · % of Row Total · Date Grouping · Calculated Fields · Cross-Sheet Data
A4: Q# | B4: Question | C4: Marks | D4: Hint | E4: Your Answer | F4: Format
A5: Q4.1 | B5: Build a pivot with sales_region as rows and product category as columns, values = SUM of final_amount. What value appears at the intersection of "South" and "Electronics"? | C5: 4 | D5: You need to add category (from Products) and region (from Sales_Reps) as columns to Orders first. Insert PivotTable from combined data. | E5: =E16 -> 1314107.4 | F5: Currency
A6: Q4.2 | B6: Build a pivot: rows = order month (Jan-24 through Dec-24), columns = sales_rep_id, values = SUM of final_amount. What is the HIGHEST single value in the entire pivot? (One number.) | C6: 4 | D6: After building, use MAX() over the pivot data range, or scan visually. | E6: =MAX(Sheet2!B6:B17) -> 15657.8 | F6: Currency
A7: Q4.3 | B7: For the North sales_region only: what PERCENTAGE of total revenue comes from the Apparel category? Configure the pivot with Show Values As → % of Row Total. | C7: 4 | D7: Pivot: rows=region, cols=category, values=sum(final_amount), Show Values As = % of Row Total. | E7: =GETPIVOTDATA("final_amount",$B$20,"Category","Apparel","Region","North") -> 0.1402315 | F7: Percentage
A8: Q4.4 | B8: Group order dates by QUARTER in a pivot. What is the total revenue for Q4 2024 (Oct-Dec)? | C8: 4 | D8: PivotTable → Group By → Quarter. Or SUMIFS with date range. | E8: =C33 -> 88776.68 | F8: Currency
A9: Q4.5 | B9: Create a CALCULATED FIELD in the pivot: profit_margin = (unit_price - unit_cost) / unit_price. What is the AVERAGE profit_margin for orders shipped to Delhi? Give as a percentage. | C9: 4 | D9: Add unit_cost via VLOOKUP as helper column. Create pivot calculated field, filter to Delhi. | E9: =F30 -> 0.51594488 | F9: Percentage
B12: Sum of final_amount | C12: Column Labels
B13: Row Labels | C13: Apparel | D13: Beauty | E13: Electronics | F13: Grocery | G13: Home | H13: Sports | I13: Grand Total
B14: East | C14: 860762.23 | D14: 1271152.8 | E14: 1214881.9 | F14: 1168089.9 | G14: 1124233.5 | H14: 945710.08 | I14: 6584830.5
B15: North | C15: 979380.97 | D15: 1556120.2 | E15: 1450710.7 | F15: 1118963.8 | G15: 867033.27 | H15: 1011820.5 | I15: 6984029.5
B16: South | C16: 962768.31 | D16: 1590646.1 | E16: 1314107.4 | F16: 1041400.8 | G16: 1140277.8 | H16: 1095843.5 | I16: 7145043.8
B17: West | C17: 868240.03 | D17: 1188460 | E17: 993053.05 | F17: 997265.82 | G17: 955407.58 | H17: 856617.89 | I17: 5859044.4
B18: Grand Total | C18: 3671151.5 | D18: 5606379.1 | E18: 4972753.1 | F18: 4325720.4 | G18: 4086952.2 | H18: 3909991.9 | I18: 26572948
B20: Sum of final_amount | C20: Column Labels
B21: Row Labels | C21: Apparel | D21: Beauty | E21: Electronics | F21: Grocery | G21: Home | H21: Sports | I21: Grand Total
B22: East | C22: 0.13071897 | D22: 0.1930426 | E22: 0.18449707 | F22: 0.17739104 | G22: 0.17073083 | H22: 0.1436195 | I22: 1
B23: North | C23: 0.1402315 | D23: 0.22281123 | E23: 0.2077183 | F23: 0.16021751 | G23: 0.12414513 | H23: 0.14487632 | I23: 1
B24: South | C24: 0.13474631 | D24: 0.22262229 | E24: 0.18391873 | F24: 0.14575149 | G24: 0.15959004 | H24: 0.15337113 | I24: 1
B25: West | C25: 0.14818799 | D25: 0.20284196 | E25: 0.16949062 | F25: 0.17020964 | G25: 0.16306543 | H25: 0.14620437 | I25: 1
B26: Grand Total | C26: 0.13815372 | D26: 0.21098069 | E26: 0.18713592 | F26: 0.16278662 | G26: 0.15380123 | H26: 0.14714182 | I26: 1
B28: Row Labels | C28: Total_Rev | E28: Row Labels | F28: Average of Profit_Margin
B29: 45292 | C29: 23681.32 | E29: Chennai | F29: 0.56137255
B30: 45293 | C30: 38974 | E30: Delhi | F30: 0.51594488
B31: 45294 | C31: 55717.08 | E31: Bengaluru | F31: 0.48061706
B32: 45295 | C32: 100652.47 | E32: Chennai | F32: 0.47321585
B33: 45296 | C33: 88776.68 | E33: Delhi | F33: 0.45936662
B34: 45297 | C34: 69631.84 | E34: Hyderabad | F34: 0.47241222
B35: 45298 | C35: 66462.14 | E35: Mumbai | F35: 0.47017176
B36: 45299 | C36: 78034.39 | E36: Pune | F36: 0.46305711
B37: 45300 | C37: 108442.52 | E37: Grand Total | F37: 0.46999495
B38: 45301 | C38: 27656.12
B39: 45302 | C39: 117167.37
B40: 45303 | C40: 76290.63
B41: 45304 | C41: 29317.6
B42: 45305 | C42: 15077.36
B43: 45306 | C43: 28366.2
B44: 45307 | C44: 120119.45
B45: 45308 | C45: 96012.68
...

Sheet Q5_Advanced
A1: Q5 - ADVANCED (10 marks total) | H1: Row Labels | I1: Sum of final_amount | K1: Total Revenue | L1: Rep Name
A2: RANK · Running Totals · TEXTJOIN · LARGE + INDEX/MATCH · Multi-condition top-N | H2: PROD-056 | I2: 260395.74 | K2: 789849.6 | L2: Rajesh Malhotra
H3: PROD-003 | I3: 248025.75 | K3: 980063.66 | L3: Sunita Malhotra
A4: Q# | B4: Question | C4: Marks | D4: Hint | E4: Your Answer | F4: Format | H4: PROD-048 | I4: 244351.2 | K4: 986692.91 | L4: Amit Singh
A5: Q5.1 | B5: Rank all sales reps by total revenue (highest = rank 1). Who (name) is at RANK #7? | C5: 2 | D5: Per-rep totals, then use RANK.EQ, or sort. Return the rep_name at position 7. | E5: =INDEX(Q3_Aggregation!L3:L32, MATCH(7, Q3_Aggregation!M3:M32, 0)) -> Amit Singh | F5: Text | H5: PROD-034 | I5: 221112.08 | K5: 589026.29 | L5: Priya Singh
A6: Q5.2 | B6: What is the CUMULATIVE revenue from Jan 2024 through the end of Aug 2024? (Sum of final_amount where order_date <= 31-Aug-2024.) | C6: 2 | D6: SUMIFS with date <=. | E6: =SUMIFS(Orders!I:I, Orders!B:B, "<="&DATE(2024,8,31)) -> 18050690 | F6: Currency | H6: PROD-004 | I6: 198124.65 | K6: 782445.33 | L6: Vikram Patel
A7: Q5.3 | B7: Among orders where the sales rep is in the WEST region: which product (by name) has the 2nd highest total revenue? | C7: 3 | D7: Helper: sales_region on orders. Filter/pivot to West, sum by product, rank, get #2, VLOOKUP product name. | E7: =VLOOKUP(H3, Products!A:B, 2, FALSE) -> Smart Watch | F7: Text | H7: PROD-025 | I7: 190994.58 | K7: 1138648.7 | L7: Neha Desai
A8: Q5.4 | B8: Concatenate the names of the top 5 reps by revenue into a single cell, separated by " | " (space-pipe-space). | C8: 2 | D8: TEXTJOIN with delimiter " | ". Combine with LARGE to pull top 5. | E8: {=_xlfn.TEXTJOIN(" | ", TRUE, INDEX(L2:L31, MATCH(LARGE(K2:K31, {1,2,3,4,5}), K2:K31, 0)))} -> Neha Desai | Shalini Patel | Deepak Shah | Nisha Menon | Arun Iyer | F8: Text | H8: PROD-026 | I8: 179739.34 | K8: 855749.68 | L8: Suresh Menon
A9: Q5.5 | B9: What is the HIGHEST single order value (final_amount) where ship_city = "Bengaluru" AND the product's category = "Grocery"? | C9: 1 | D9: MAXIFS with a category helper column, or nested MAX(IF()). | E9: =_xlfn.MAXIFS(Orders!I1:I2001,Orders!K1:K2001, "Bengaluru",Orders!L1:L2001, "Grocery") -> 22134 | F9: Currency | H9: PROD-039 | I9: 177512.66 | K9: 861553.33 | L9: Kavita Patel
H10: PROD-047 | I10: 167780.4 | K10: 914554.72 | L10: Manoj Patel
H11: PROD-001 | I11: 155358.84 | K11: 880345.2 | L11: Divya Rao
H12: PROD-059 | I12: 150054.66 | K12: 735207.76 | L12: Anil Verma
H13: PROD-011 | I13: 145224.3 | K13: 901394.32 | L13: Pooja Nair
H14: PROD-042 | I14: 138799.19 | K14: 811524.38 | L14: Sanjay Kapoor
H15: PROD-033 | I15: 137585.28 | K15: 995713.54 | L15: Ritu Menon
H16: PROD-050 | I16: 124646.08 | K16: 1091740.2 | L16: Deepak Shah
H17: PROD-012 | I17: 121770.6 | K17: 814563.71 | L17: Anjali Chopra
H18: PROD-038 | I18: 119445.93 | K18: 780384.41 | L18: Naveen Singh
H19: PROD-029 | I19: 118562.08 | K19: 1112289.6 | L19: Shalini Patel
H20: PROD-028 | I20: 112574.28 | K20: 971183.52 | L20: Prakash Shah
H21: PROD-055 | I21: 109566.6 | K21: 906107.71 | L21: Meera Iyer
... H31: PROD-046 | I31: 100035.12 | K31: 747624.37 | L31: Kiran Bhatt
H32: PROD-014 | I32: 95390.62
H33: PROD-021 | I33: 90555.6
H34: PROD-036 | I34: 88426
H35: PROD-013 | I35: 85543.64
H36: PROD-017 | I36: 84699.95
H37: PROD-023 | I37: 84480.48
H38: PROD-041 | I38: 80488.1
H39: PROD-024 | I39: 77055.15
H40: PROD-052 | I40: 74614.72
H41: PROD-058 | I41: 71772
H42: PROD-044 | I42: 68328.15
H43: PROD-010 | I43: 67393.92
... H62: Grand Total | I62: 5859044.4

Sheet Sheet2
A3: Sum of final_amount | B3: Column Labels
A4: Row Labels | B4: R001 | C4: R002 | D4: R003 | E4: R004 | F4: R005 | G4: R006 | H4: R007 | I4: R008 | J4: R009 | K4: R010 | L4: R011 | M4: R012 | N4: R013 | O4: R014 | P4: R015 | Q4: R016 | R4: R017 | S4: R018 | T4: R019 | U4: R020 | V4: R021 | W4: R022 | X4: R023 | Y4: R024 | Z4: R025 | AA4: R026 | AB4: R027 | AC4: R028 | AD4: R029 | AE4: R030 | AF4: Grand Total
A5: 45292 | O5: 4389.76 | P5: 19291.56 | AF5: 23681.32
A6: 45293 | C6: 4650.52 | I6: 3583.48 | O6: 27236.16 | AE6: 3503.84 | AF6: 38974
A7: 45294 | C7: 4529.6 | L7: 23517 | M7: 13890.52 | S7: 11090.04 | V7: 2689.92 | AF7: 55717.08
A8: 45295 | C8: 15565.2 | H8: 25251.75 | I8: 23718.4 | S8: 10057.68 | Y8: 5599.44 | AB8: 20460 | AF8: 100652.47
A9: 45296 | F9: 9692.55 | H9: 3201.66 | K9: 36377.25 | M9: 26945.64 | R9: 7383.9 | U9: 932.9 | W9: 4242.78 | AF9: 88776.68
A10: 45297 | D10: 42000.4 | G10: 16374.96 | U10: 8522.4 | Y10: 2734.08 | AF10: 69631.84
A11: 45298 | B11: 15657.8 | E11: 5178.24 | G11: 9791.1 | N11: 14858.76 | W11: 16896.24 | Y11: 4080 | AF11: 66462.14
A12: 45299 | F12: 12395.04 | I12: 16197.54 | L12: 6073.92 | P12: 6372.4 | R12: 24078.6 | AD12: 12916.89 | AF12: 78034.39
A13: 45300 | C13: 10028.2 | D13: 12306.6 | P13: 21574 | U13: 8344.52 | X13: 4945.08 | Z13: 38120.32 | AC13: 13123.8 | AF13: 108442.52
A14: 45301 | H14: 2577 | N14: 15646.8 | O14: 2671.5 | R14: 3736.26 | X14: 3024.56 | AF14: 27656.12
A15: 45302 | C15: 13759.2 | F15: 21969.6 | J15: 26290.8 | AD15: 18162.9 | AE15: 36984.87 | AF15: 117167.37
A16: 45303 | O16: 38432.64 | R16: 5368.89 | W16: 32489.1 | AF16: 76290.63
A17: 45304 | J17: 9821 | Q17: 6973.04 | Y17: 12523.56 | AF17: 29317.6
A18: 45305 | G18: 12868.56 | U18: 2208.8 | AF18: 15077.36
A19: 45306 | C19: 3174.6 | F19: 2867.5 | R19: 14938.56 | U19: 2347.36 | AB19: 4076.92 | AD19: 961.26 | AF19: 28366.2
A20: 45307 | E20: 2132.65 | P20: 9715.84 | R20: 13994.82 | S20: 29078.6 | X20: 31550.38 | Z20: 10909.08 | AC20: 22738.08 | AF20: 120119.45
A21: 45308 | F21: 9056.64 | H21: 18921.5 | J21: 37881.54 | Q21: 30153 | AF21: 96012.68
A22: 45309 | B22: 8266.56 | E22: 40566.6 | F22: 8261.12 | O22: 6583.68 | AF22: 63677.96
A23: 45310 | B23: 19726.2 | S23: 9460.5 | U23: 6074.88 | AC23: 712.12 | AF23: 35973.7
A24: 45311 | H24: 35295 | T24: 13147.38 | AF24: 48442.38
A25: 45312 | G25: 35732.32 | K25: 5530.56 | M25: 6661.62 | P25: 31060.26 | U25: 2921.52 | AA25: 2040.18 | AE25: 18682.1 | AF25: 102628.56
A26: 45313 | J26: 43962 | M26: 1059.06 | S26: 21390.08 | AF26: 66411.14
A27: 45314 | R27: 2449.76 | Z27: 7012.44 | AF27: 9462.2
A28: 45315 | M28: 16229.12 | N28: 11122.38 | O28: 8184 | X28: 10556.7 | AF28: 46092.2
A29: 45316 | E29: 10014.62 | L29: 33782.4 | Q29: 25069.8 | X29: 2724.48 | AB29: 26109.6 | AF29: 97700.9
A30: 45317 | H30: 6783 | I30: 18057.6 | N30: 2796.6 | W30: 21463.2 | AF30: 49100.4
A31: 45318 | F31: 6423.06 | L31: 25418.4 | T31: 15931 | W31: 19299.42 | AB31: 14967.44 | AF31: 82039.32
A32: 45319 | M32: 5894.07 | N32: 7184.58 | R32: 1905.6 | U32: 10392.06 | AB32: 8496 | AD32: 13328.1 | AF32: 47200.41
A33: 45320 | S33: 20561.6 | W33: 31937 | AF33: 52498.6
A34: 45321 | P34: 30887 | W34: 31880.1 | AA34: 10727.64 | AF34: 73494.74
A35: 45322 | G35: 10201.62 | J35: 7592.2 | K35: 1170.4 | T35: 1816.8 | X35: 1804.86 | AB35: 3459.2 | AF35: 26045.08
A36: 45323 | K36: 21630.6 | X36: 27008.73 | AC36: 17165.68 | AE36: 3129.84 | AF36: 68934.85
A37: 45324 | C37: 4181.52 | D37: 32452 | E37: 29842.5 | L37: 3590.46 | O37: 15743.7 | P37: 15753 | Q37: 1073.16 | AB37: 10403.88 | AF37: 113040.22
A38: 45325 | E38: 6070.1 | X38: 21915.12 | Z38: 14162.3 | AF38: 42147.52
A39: 45326 | M39: 23543.76 | AB39: 6855.42 | AE39: 5779.4 | AF39: 36178.58
A40: 45327 | K40: 20327.4 | S40: 10580.32 | AD40: 42625.66 | AF40: 73533.38
A41: 45328 | B41: 37696.88 | F41: 18772.9 | L41: 2616 | M41: 6329.4 | O41: 16107.84 | R41: 5857.16 | Y41: 19214.08 | Z41: 2883.29 | AB41: 1516.96 | AD41: 22134 | AF41: 133128.51
A42: 45329 | B42: 9507.42 | F42: 19519.28 | H42: 19637.7 | I42: 2762.1 | N42: 2791.05 | T42: 17439.9 | V42: 15856.2 | W42: 2271.64 | AF42: 89785.29
...

Sheet Sheet7
A1: Region | B1: West
A3: Row Labels | B3: Sum of final_amount
A4: PROD-056 | B4: 260395.74
A5: PROD-003 | B5: 248025.75
A6: PROD-048 | B6: 244351.2
A7: PROD-034 | B7: 221112.08
A8: PROD-004 | B8: 198124.65
A9: PROD-025 | B9: 190994.58
A10: PROD-026 | B10: 179739.34
A11: PROD-039 | B11: 177512.66
A12: PROD-047 | B12: 167780.4
A13: PROD-001 | B13: 155358.84
A14: PROD-059 | B14: 150054.66
A15: PROD-011 | B15: 145224.3
... A64: Grand Total | B64: 5859044.4
